Workbook

Sheet README
A1: Food Delivery Data Cleaning Workbook
A2: SYNTHETIC practice data (generated for learning) - modelled on Indian food-delivery apps like Swiggy / Zomato. Not real company data.
A4: Sheet | B4: What it contains / what you do there
A5: Data_Dictionary | B5: Meaning of every column in simple English.
A6: Raw_Data | B6: Columns A-N = the messy raw data exactly as received (never edit these). Green columns O-AH = helper formulas that FLAG problems and show the CLEAN version of each field.
A7: Map_Tables | B7: Lookup tables used to standardise city, payment method and restaurant names (like a "translation dictionary").
A8: Cleaned_Data | B8: The final cleaned dataset (values only, except Net_Amount which is a formula). This is what you import into MySQL and Power BI.
A9: Cleaning_Log | B9: Rows before/after, why rows were removed, missing-value report and decisions. All numbers are live formulas.
A10: Outlier_Check | B10: IQR (box-plot) method to find unusual order values and delivery times.
A11: Summary | B11: Formula-based summary tables (same result a PivotTable gives). Build the real PivotTable yourself using the steps in the Excel guide.
A12: Formula_Lab | B12: One working example of each formula you were asked to learn: IF, IFERROR, COUNTIF(S), SUMIF(S), lookup, TRIM.
A14: Colour legend
A15: Dark blue header | B15: Original raw / final data columns
A16: Green header | B16: Helper formula columns (flags and cleaned values)
A17: Yellow cell | B17: An input cell you can change and watch the formula react
A18: Red / orange cell (Raw_Data) | B18: Conditional formatting: red = missing/duplicate/drop, orange = missing delivery time or rating on a delivered order, yellow = invalid value
A20: Business rule for sales | B20: Net_Amount = Quantity x Unit_Price - Discount_Amount. SALES count only orders with Order_Status = Delivered. Cancelled orders are never counted as sales.
A21: Date note | B21: Slash dates in raw data are DD/MM/YYYY (Indian format).

Sheet Data_Dictionary
A1: Data Dictionary
A2: What each column means (simple English)
A4: Column | B4: Data type | C4: Meaning
A5: order_id | B5: Text | C5: Unique ID of one order, e.g. ORD10001. Every order must appear only once.
A6: order_date | B6: Date | C6: Day the customer placed the order (2025). Raw file has 3 different date styles.
A7: order_time | B7: Text HH:MM | C7: Time of day the order was placed (24-hour clock). Used for peak-hour analysis.
A8: customer_id | B8: Text | C8: Unique ID of the customer, e.g. C0123. Used to find repeat customers.
A9: restaurant_name | B9: Text | C9: Restaurant that cooked the food (fictional names).
A10: city | B10: Text | C10: City where the order was delivered (8 Indian cities).
A11: cuisine | B11: Text | C11: Type of food: North Indian, South Indian, Biryani, Chinese, Pizza, Burgers, Street Food, Desserts, Healthy Food.
A12: quantity | B12: Whole number | C12: Number of items in the order. Valid range used here: 1 to 10.
A13: unit_price | B13: Number (Rs) | C13: Price of one item in Indian Rupees. Valid range used here: Rs 1 to Rs 1,500.
A14: discount_amount | B14: Number (Rs) | C14: Total discount (coupon/offer) on the whole order in Rs. Cannot be more than Quantity x Unit Price.
A15: net_amount | B15: Number (Rs) | C15: Cleaned file only. What the customer pays for food = Quantity x Unit Price - Discount. Delivery/tax fees are not included.
... A19: customer_rating | B19: Whole number 1-5 | C19: Star rating given after delivery. Blank if cancelled or customer did not rate.

Sheet Map_Tables
A1: Lookup (mapping) tables
A2: Key = any spelling found in raw data. Lookup is NOT case sensitive, and TRIM removes extra spaces first.
A3: City (raw spelling) | B3: City (standard) | D3: Payment (raw spelling) | E3: Payment (standard) | G3: Restaurant (raw spelling) | H3: Restaurant (standard) | I3: Restaurant city | J3: Cuisine
A4: bangalore | B4: Bengaluru | D4: upi | E4: UPI | G4: Spice Junction | H4: Spice Junction | I4: Bengaluru | J4: North Indian
A5: bengaluru | B5: Bengaluru | D5: credit card | E5: Credit Card | G5: Dosa Darbar | H5: Dosa Darbar | I5: Bengaluru | J5: South Indian
A6: blr | B6: Bengaluru | D6: cc | E6: Credit Card | G6: Nawabi Biryani House | H6: Nawabi Biryani House | I6: Bengaluru | J6: Biryani
A7: mumbai | B7: Mumbai | D7: debit card | E7: Debit Card | G7: Wok & Roll | H7: Wok & Roll | I7: Bengaluru | J7: Chinese
A8: bombay | B8: Mumbai | D8: dc | E8: Debit Card | G8: Wok and Roll | H8: Wok & Roll | I8: Bengaluru | J8: Chinese
A9: delhi | B9: Delhi | D9: cod | E9: Cash on Delivery | G9: Curry Leaf Kitchen | H9: Curry Leaf Kitchen | I9: Mumbai | J9: North Indian
A10: new delhi | B10: Delhi | D10: cash on delivery | E10: Cash on Delivery | G10: Pav Bhaji Point | H10: Pav Bhaji Point | I10: Mumbai | J10: Street Food
A11: hyderabad | B11: Hyderabad | D11: wallet | E11: Wallet | G11: Mumbai Pizza Co | H11: Mumbai Pizza Co | I11: Mumbai | J11: Pizza
A12: hyd | B12: Hyderabad | D12: paytm wallet | E12: Wallet | G12: Dragon Express | H12: Dragon Express | I12: Mumbai | J12: Chinese
A13: chennai | B13: Chennai | D13: e-wallet | E13: Wallet | G13: Tandoor Tales | H13: Tandoor Tales | I13: Delhi | J13: North Indian
A14: madras | B14: Chennai | D14: net banking | E14: Net Banking | G14: Chaat Corner | H14: Chaat Corner | I14: Delhi | J14: Street Food
A15: pune | B15: Pune | D15: netbanking | E15: Net Banking | G15: Burger Barn | H15: Burger Barn | I15: Delhi | J15: Burgers
A16: kolkata | B16: Kolkata | G16: Momo Magic | H16: Momo Magic | I16: Delhi | J16: Chinese
A17: calcutta | B17: Kolkata | G17: Hyderabad Dum Biryani | H17: Hyderabad Dum Biryani | I17: Hyderabad | J17: Biryani
A18: ahmedabad | B18: Ahmedabad | G18: Andhra Meals Mess | H18: Andhra Meals Mess | I18: Hyderabad | J18: South Indian
G19: Pizza Palace | H19: Pizza Palace | I19: Hyderabad | J19: Pizza
G20: Sweet Tooth Studio | H20: Sweet Tooth Studio | I20: Hyderabad | J20: Desserts
G21: Chettinad House | H21: Chettinad House | I21: Chennai | J21: South Indian
G22: Filter Coffee & Tiffin | H22: Filter Coffee & Tiffin | I22: Chennai | J22: South Indian
G23: Filter Coffee and Tiffin | H23: Filter Coffee & Tiffin | I23: Chennai | J23: South Indian
G24: Madras Biryani Co | H24: Madras Biryani Co | I24: Chennai | J24: Biryani
G25: Green Bowl Kitchen | H25: Green Bowl Kitchen | I25: Chennai | J25: Healthy Food
G26: Misal Mantra | H26: Misal Mantra | I26: Pune | J26: Street Food
G27: Pune Burger Hub | H27: Pune Burger Hub | I27: Pune | J27: Burgers
G28: Maratha Thali House | H28: Maratha Thali House | I28: Pune | J28: North Indian
G29: Cake Walk | H29: Cake Walk | I29: Pune | J29: Desserts
G30: Bengal Bites | H30: Bengal Bites | I30: Kolkata | J30: Street Food
... G37: Cheesy Slice | H37: Cheesy Slice | I37: Ahmedabad | J37: Pizza

Sheet Raw_Data
A1: order_id | B1: order_date | C1: order_time | D1: customer_id | E1: restaurant_name | F1: city | G1: cuisine | H1: quantity | I1: unit_price | J1: discount_amount | K1: payment_method | L1: order_status | M1: delivery_time_min | N1: customer_rating | O1: row_key | P1: exact_dup_check | Q1: blank_count | R1: rows_with_same_order_id | S1: order_id_action | T1: missing_order_id | U1: missing_customer_id | V1: missing_restaurant | W1: invalid_quantity | X1: invalid_price | Y1: discount_gt_order_value | Z1: invalid_rating | AA1: invalid_delivery_time | AB1: drop_reason | AC1: keep_or_drop | AD1: city_clean | AE1: restaurant_clean | AF1: payment_clean | AG1: status_clean | AH1: date_clean
A2: ORD10675 | B2: 2025-03-27 | C2: 12:57 | D2: C0623 | E2: Sweet Tooth Studio | F2: Hyderabad | G2: Desserts | H2: 2 | I2: 180 | J2: 0 | K2: UPI | L2: Delivered | M2: 17 | N2: 5 | O2: =A2&"|"&B2&"|"&C2&"|"&D2&"|"&E2&"|"&F2&"|"&G2&"|"&H2&"|"&I2&"|"&J2&"|"&K2&"|"&L2&"|"&M2&"|"&N2 -> ORD10675|2025-03-27|12:57|C0623|Sweet Tooth Studio |Hyderabad|Desserts|2|180|0|UPI|Delivered|17|5 | P2: =IF(COUNTIF($O$2:O2,O2)>1,"DUP","OK") -> OK | Q2: =COUNTBLANK(A2:N2) -> 0 | R2: =IF(A2="",0,COUNTIFS($A$2:$A$3058,A2,$P$2:$P$3058,"OK")) -> 1 | S2: =IF(OR(A2="",P2="DUP",R2<2),"",IF(Q2=_xlfn.MINIFS($Q$2:$Q$3058,$A$2:$A$3058,A2,$P$2:$P$3058,"OK"),"KEEP","DROP")) | T2: =IF(A2="",1,0) -> 0 | U2: =IF(D2="",1,0) -> 0 | V2: =IF(E2="",1,0) -> 0 | W2: =IF(OR(H2<1,H2>10),1,0) -> 0 | X2: =IF(OR(I2<=0,I2>1500),1,0) -> 0 | Y2: =IF(J2>H2*I2,1,0) -> 0 | Z2: =IF(AND(N2<>"",OR(N2<1,N2>5)),1,0) -> 0 | AA2: =IF(AND(M2<>"",OR(M2<5,M2>180)),1,0) -> 0 | AB2: =IF(P2="DUP","Exact duplicate row",IF(T2=1,"Missing Order ID",IF(S2="DROP","Duplicate Order ID (less complete row)",IF(U2=1,"Missing Customer ID",IF(V2=1,"Missing Restaurant name",IF(W2=1,"Invalid/outlier quantity",IF(X2=1,"Invalid/outlier unit price",IF(Y2=1,"Discount greater than order value","")))))))) | AC2: =IF(AB2="","KEEP","DROP") -> KEEP | AD2: =IF(TRIM(F2)="",IFERROR(INDEX(Map_Tables!$I$4:$I$37,MATCH(TRIM(E2),Map_Tables!$G$4:$G$37,0)),""),IFERROR(INDEX(Map_Tables!$B$4:$B$18,MATCH(TRIM(F2),Map_Tables!$A$4:$A$18,0)),"CHECK")) -> Hyderabad | AE2: =IF(TRIM(E2)="","",IFERROR(INDEX(Map_Tables!$H$4:$H$37,MATCH(TRIM(E2),Map_Tables!$G$4:$G$37,0)),"CHECK")) -> Sweet Tooth Studio | AF2: =IF(TRIM(K2)="","Unknown",IFERROR(INDEX(Map_Tables!$E$4:$E$15,MATCH(TRIM(K2),Map_Tables!$D$4:$D$15,0)),"CHECK")) -> UPI | AG2: =IF(LEFT(LOWER(TRIM(L2)),6)="cancel","Cancelled","Delivered") -> Delivered | AH2: =IF(ISNUMBER(SEARCH("/",B2)),DATE(VALUE(RIGHT(B2,4)),VALUE(MID(B2,4,2)),VALUE(LEFT(B2,2))),IF(MID(B2,5,1)="-",DATE(VALUE(LEFT(B2,4)),VALUE(MID(B2,6,2)),VALUE(RIGHT(B2,2))),DATE(VALUE(RIGHT(B2,4)),MATCH(MID(B2,4,3),{"Jan","Feb","Mar","Apr","May","Jun","Jul","Aug","Sep","Oct","Nov","Dec"},0),VALUE(LEFT(B2,2))))) -> 45743
A3: ORD12670 | B3: 2025-11-24 | C3: 22:08 | D3: C0449 | E3: Chaat Corner | F3: Delhi | G3: Street Food | H3: 4 | I3: 95 | J3: 30 | K3: UPI | L3: Delivered | M3: 47 | N3: 3 | O3: =A3&"|"&B3&"|"&C3&"|"&D3&"|"&E3&"|"&F3&"|"&G3&"|"&H3&"|"&I3&"|"&J3&"|"&K3&"|"&L3&"|"&M3&"|"&N3 -> ORD12670|2025-11-24|22:08|C0449|Chaat Corner|Delhi|Street Food|4|95|30|UPI|Delivered|47|3 | P3: =IF(COUNTIF($O$2:O3,O3)>1,"DUP","OK") -> OK | Q3: =COUNTBLANK(A3:N3) -> 0 | R3: =IF(A3="",0,COUNTIFS($A$2:$A$3058,A3,$P$2:$P$3058,"OK")) -> 1 | S3: =IF(OR(A3="",P3="DUP",R3<2),"",IF(Q3=_xlfn.MINIFS($Q$2:$Q$3058,$A$2:$A$3058,A3,$P$2:$P$3058,"OK"),"KEEP","DROP")) | T3: =IF(A3="",1,0) -> 0 | U3: =IF(D3="",1,0) -> 0 | V3: =IF(E3="",1,0) -> 0 | W3: =IF(OR(H3<1,H3>10),1,0) -> 0 | X3: =IF(OR(I3<=0,I3>1500),1,0) -> 0 | Y3: =IF(J3>H3*I3,1,0) -> 0 | Z3: =IF(AND(N3<>"",OR(N3<1,N3>5)),1,0) -> 0 | AA3: =IF(AND(M3<>"",OR(M3<5,M3>180)),1,0) -> 0 | AB3: =IF(P3="DUP","Exact duplicate row",IF(T3=1,"Missing Order ID",IF(S3="DROP","Duplicate Order ID (less complete row)",IF(U3=1,"Missing Customer ID",IF(V3=1,"Missing Restaurant name",IF(W3=1,"Invalid/outlier quantity",IF(X3=1,"Invalid/outlier unit price",IF(Y3=1,"Discount greater than order value","")))))))) | AC3: =IF(AB3="","KEEP","DROP") -> KEEP | AD3: =IF(TRIM(F3)="",IFERROR(INDEX(Map_Tables!$I$4:$I$37,MATCH(TRIM(E3),Map_Tables!$G$4:$G$37,0)),""),IFERROR(INDEX(Map_Tables!$B$4:$B$18,MATCH(TRIM(F3),Map_Tables!$A$4:$A$18,0)),"CHECK")) -> Delhi | AE3: =IF(TRIM(E3)="","",IFERROR(INDEX(Map_Tables!$H$4:$H$37,MATCH(TRIM(E3),Map_Tables!$G$4:$G$37,0)),"CHECK")) -> Chaat Corner | AF3: =IF(TRIM(K3)="","Unknown",IFERROR(INDEX(Map_Tables!$E$4:$E$15,MATCH(TRIM(K3),Map_Tables!$D$4:$D$15,0)),"CHECK")) -> UPI | AG3: =IF(LEFT(LOWER(TRIM(L3)),6)="cancel","Cancelled","Delivered") -> Delivered | AH3: =IF(ISNUMBER(SEARCH("/",B3)),DATE(VALUE(RIGHT(B3,4)),VALUE(MID(B3,4,2)),VALUE(LEFT(B3,2))),IF(MID(B3,5,1)="-",DATE(VALUE(LEFT(B3,4)),VALUE(MID(B3,6,2)),VALUE(RIGHT(B3,2))),DATE(VALUE(RIGHT(B3,4)),MATCH(MID(B3,4,3),{"Jan","Feb","Mar","Apr","May","Jun","Jul","Aug","Sep","Oct","Nov","Dec"},0),VALUE(LEFT(B3,2))))) -> 45985
A4: ORD10378 | B4: 2025-02-19 | C4: 20:46 | D4: C0376 | E4: Chettinad House | F4: Chennai | G4: South Indian | H4: 1 | I4: 160 | J4: 64 | K4: Cash on Delivery | L4: Delivered | M4: 51 | N4: 3 | O4: =A4&"|"&B4&"|"&C4&"|"&D4&"|"&E4&"|"&F4&"|"&G4&"|"&H4&"|"&I4&"|"&J4&"|"&K4&"|"&L4&"|"&M4&"|"&N4 -> ORD10378|2025-02-19|20:46|C0376|Chettinad House|Chennai|South Indian|1|160|64|Cash on Delivery|Delivered|51|3 | P4: =IF(COUNTIF($O$2:O4,O4)>1,"DUP","OK") -> OK | Q4: =COUNTBLANK(A4:N4) -> 0 | R4: =IF(A4="",0,COUNTIFS($A$2:$A$3058,A4,$P$2:$P$3058,"OK")) -> 1 | S4: =IF(OR(A4="",P4="DUP",R4<2),"",IF(Q4=_xlfn.MINIFS($Q$2:$Q$3058,$A$2:$A$3058,A4,$P$2:$P$3058,"OK"),"KEEP","DROP")) | T4: =IF(A4="",1,0) -> 0 | U4: =IF(D4="",1,0) -> 0 | V4: =IF(E4="",1,0) -> 0 | W4: =IF(OR(H4<1,H4>10),1,0) -> 0 | X4: =IF(OR(I4<=0,I4>1500),1,0) -> 0 | Y4: =IF(J4>H4*I4,1,0) -> 0 | Z4: =IF(AND(N4<>"",OR(N4<1,N4>5)),1,0) -> 0 | AA4: =IF(AND(M4<>"",OR(M4<5,M4>180)),1,0) -> 0 | AB4: =IF(P4="DUP","Exact duplicate row",IF(T4=1,"Missing Order ID",IF(S4="DROP","Duplicate Order ID (less complete row)",IF(U4=1,"Missing Customer ID",IF(V4=1,"Missing Restaurant name",IF(W4=1,"Invalid/outlier quantity",IF(X4=1,"Invalid/outlier unit price",IF(Y4=1,"Discount greater than order value","")))))))) | AC4: =IF(AB4="","KEEP","DROP") -> KEEP | AD4: =IF(TRIM(F4)="",IFERROR(INDEX(Map_Tables!$I$4:$I$37,MATCH(TRIM(E4),Map_Tables!$G$4:$G$37,0)),""),IFERROR(INDEX(Map_Tables!$B$4:$B$18,MATCH(TRIM(F4),Map_Tables!$A$4:$A$18,0)),"CHECK")) -> Chennai | AE4: =IF(TRIM(E4)="","",IFERROR(INDEX(Map_Tables!$H$4:$H$37,MATCH(TRIM(E4),Map_Tables!$G$4:$G$37,0)),"CHECK")) -> Chettinad House | AF4: =IF(TRIM(K4)="","Unknown",IFERROR(INDEX(Map_Tables!$E$4:$E$15,MATCH(TRIM(K4),Map_Tables!$D$4:$D$15,0)),"CHECK")) -> Cash on Delivery | AG4: =IF(LEFT(LOWER(TRIM(L4)),6)="cancel","Cancelled","Delivered") -> Delivered | AH4: =IF(ISNUMBER(SEARCH("/",B4)),DATE(VALUE(RIGHT(B4,4)),VALUE(MID(B4,4,2)),VALUE(LEFT(B4,2))),IF(MID(B4,5,1)="-",DATE(VALUE(LEFT(B4,4)),VALUE(MID(B4,6,2)),VALUE(RIGHT(B4,2))),DATE(VALUE(RIGHT(B4,4)),MATCH(MID(B4,4,3),{"Jan","Feb","Mar","Apr","May","Jun","Jul","Aug","Sep","Oct","Nov","Dec"},0),VALUE(LEFT(B4,2))))) -> 45707
A5: ORD10803 | B5: 2025-04-12 | C5: 00:02 | D5: C0164 | E5: Pav Bhaji Point | F5: Mumbai | G5: Street Food | H5: 5 | I5: 140 | J5: 50 | K5: Debit Card | L5: Delivered | M5: 55 | N5: 3 | O5: =A5&"|"&B5&"|"&C5&"|"&D5&"|"&E5&"|"&F5&"|"&G5&"|"&H5&"|"&I5&"|"&J5&"|"&K5&"|"&L5&"|"&M5&"|"&N5 -> ORD10803|2025-04-12|00:02|C0164|Pav Bhaji Point|Mumbai|Street Food|5|140|50|Debit Card|Delivered|55|3 | P5: =IF(COUNTIF($O$2:O5,O5)>1,"DUP","OK") -> OK | Q5: =COUNTBLANK(A5:N5) -> 0 | R5: =IF(A5="",0,COUNTIFS($A$2:$A$3058,A5,$P$2:$P$3058,"OK")) -> 1 | S5: =IF(OR(A5="",P5="DUP",R5<2),"",IF(Q5=_xlfn.MINIFS($Q$2:$Q$3058,$A$2:$A$3058,A5,$P$2:$P$3058,"OK"),"KEEP","DROP")) | T5: =IF(A5="",1,0) -> 0 | U5: =IF(D5="",1,0) -> 0 | V5: =IF(E5="",1,0) -> 0 | W5: =IF(OR(H5<1,H5>10),1,0) -> 0 | X5: =IF(OR(I5<=0,I5>1500),1,0) -> 0 | Y5: =IF(J5>H5*I5,1,0) -> 0 | Z5: =IF(AND(N5<>"",OR(N5<1,N5>5)),1,0) -> 0 | AA5: =IF(AND(M5<>"",OR(M5<5,M5>180)),1,0) -> 0 | AB5: =IF(P5="DUP","Exact duplicate row",IF(T5=1,"Missing Order ID",IF(S5="DROP","Duplicate Order ID (less complete row)",IF(U5=1,"Missing Customer ID",IF(V5=1,"Missing Restaurant name",IF(W5=1,"Invalid/outlier quantity",IF(X5=1,"Invalid/outlier unit price",IF(Y5=1,"Discount greater than order value","")))))))) | AC5: =IF(AB5="","KEEP","DROP") -> KEEP | AD5: =IF(TRIM(F5)="",IFERROR(INDEX(Map_Tables!$I$4:$I$37,MATCH(TRIM(E5),Map_Tables!$G$4:$G$37,0)),""),IFERROR(INDEX(Map_Tables!$B$4:$B$18,MATCH(TRIM(F5),Map_Tables!$A$4:$A$18,0)),"CHECK")) -> Mumbai | AE5: =IF(TRIM(E5)="","",IFERROR(INDEX(Map_Tables!$H$4:$H$37,MATCH(TRIM(E5),Map_Tables!$G$4:$G$37,0)),"CHECK")) -> Pav Bhaji Point | AF5: =IF(TRIM(K5)="","Unknown",IFERROR(INDEX(Map_Tables!$E$4:$E$15,MATCH(TRIM(K5),Map_Tables!$D$4:$D$15,0)),"CHECK")) -> Debit Card | AG5: =IF(LEFT(LOWER(TRIM(L5)),6)="cancel","Cancelled","Delivered") -> Delivered | AH5: =IF(ISNUMBER(SEARCH("/",B5)),DATE(VALUE(RIGHT(B5,4)),VALUE(MID(B5,4,2)),VALUE(LEFT(B5,2))),IF(MID(B5,5,1)="-",DATE(VALUE(LEFT(B5,4)),VALUE(MID(B5,6,2)),VALUE(RIGHT(B5,2))),DATE(VALUE(RIGHT(B5,4)),MATCH(MID(B5,4,3),{"Jan","Feb","Mar","Apr","May","Jun","Jul","Aug","Sep","Oct","Nov","Dec"},0),VALUE(LEFT(B5,2))))) -> 45759
A6: ORD11209 | B6: 02/06/2025 | C6: 21:40 | D6: C1083 | E6: Cheesy Slice | F6: Ahmedabad | G6: Pizza | H6: 1 | I6: 290 | J6: 116 | K6: Cash on Delivery | L6: Delivered | M6: 30 | O6: =A6&"|"&B6&"|"&C6&"|"&D6&"|"&E6&"|"&F6&"|"&G6&"|"&H6&"|"&I6&"|"&J6&"|"&K6&"|"&L6&"|"&M6&"|"&N6 -> ORD11209|02/06/2025|21:40|C1083|Cheesy Slice|Ahmedabad|Pizza|1|290|116|Cash on Delivery|Delivered|30| | P6: =IF(COUNTIF($O$2:O6,O6)>1,"DUP","OK") -> OK | Q6: =COUNTBLANK(A6:N6) -> 1 | R6: =IF(A6="",0,COUNTIFS($A$2:$A$3058,A6,$P$2:$P$3058,"OK")) -> 1 | S6: =IF(OR(A6="",P6="DUP",R6<2),"",IF(Q6=_xlfn.MINIFS($Q$2:$Q$3058,$A$2:$A$3058,A6,$P$2:$P$3058,"OK"),"KEEP","DROP")) | T6: =IF(A6="",1,0) -> 0 | U6: =IF(D6="",1,0) -> 0 | V6: =IF(E6="",1,0) -> 0 | W6: =IF(OR(H6<1,H6>10),1,0) -> 0 | X6: =IF(OR(I6<=0,I6>1500),1,0) -> 0 | Y6: =IF(J6>H6*I6,1,0) -> 0 | Z6: =IF(AND(N6<>"",OR(N6<1,N6>5)),1,0) -> 0 | AA6: =IF(AND(M6<>"",OR(M6<5,M6>180)),1,0) -> 0 | AB6: =IF(P6="DUP","Exact duplicate row",IF(T6=1,"Missing Order ID",IF(S6="DROP","Duplicate Order ID (less complete row)",IF(U6=1,"Missing Customer ID",IF(V6=1,"Missing Restaurant name",IF(W6=1,"Invalid/outlier quantity",IF(X6=1,"Invalid/outlier unit price",IF(Y6=1,"Discount greater than order value","")))))))) | AC6: =IF(AB6="","KEEP","DROP") -> KEEP | AD6: =IF(TRIM(F6)="",IFERROR(INDEX(Map_Tables!$I$4:$I$37,MATCH(TRIM(E6),Map_Tables!$G$4:$G$37,0)),""),IFERROR(INDEX(Map_Tables!$B$4:$B$18,MATCH(TRIM(F6),Map_Tables!$A$4:$A$18,0)),"CHECK")) -> Ahmedabad | AE6: =IF(TRIM(E6)="","",IFERROR(INDEX(Map_Tables!$H$4:$H$37,MATCH(TRIM(E6),Map_Tables!$G$4:$G$37,0)),"CHECK")) -> Cheesy Slice | AF6: =IF(TRIM(K6)="","Unknown",IFERROR(INDEX(Map_Tables!$E$4:$E$15,MATCH(TRIM(K6),Map_Tables!$D$4:$D$15,0)),"CHECK")) -> Cash on Delivery | AG6: =IF(LEFT(LOWER(TRIM(L6)),6)="cancel","Cancelled","Delivered") -> Delivered | AH6: =IF(ISNUMBER(SEARCH("/",B6)),DATE(VALUE(RIGHT(B6,4)),VALUE(MID(B6,4,2)),VALUE(LEFT(B6,2))),IF(MID(B6,5,1)="-",DATE(VALUE(LEFT(B6,4)),VALUE(MID(B6,6,2)),VALUE(RIGHT(B6,2))),DATE(VALUE(RIGHT(B6,4)),MATCH(MID(B6,4,3),{"Jan","Feb","Mar","Apr","May","Jun","Jul","Aug","Sep","Oct","Nov","Dec"},0),VALUE(LEFT(B6,2))))) -> 45810
A7: ORD12737 | B7: 2025-12-01 | C7: 20:37 | D7: C0481 | E7: Mumbai Pizza Co | F7: MUMBAI | G7: Pizza | H7: 3 | I7: 375 | J7: 0 | K7: Net Banking | L7: Delivered | M7: 39 | N7: 4 | O7: =A7&"|"&B7&"|"&C7&"|"&D7&"|"&E7&"|"&F7&"|"&G7&"|"&H7&"|"&I7&"|"&J7&"|"&K7&"|"&L7&"|"&M7&"|"&N7 -> ORD12737|2025-12-01|20:37|C0481|Mumbai Pizza Co|MUMBAI|Pizza|3|375|0|Net Banking|Delivered|39|4 | P7: =IF(COUNTIF($O$2:O7,O7)>1,"DUP","OK") -> OK | Q7: =COUNTBLANK(A7:N7) -> 0 | R7: =IF(A7="",0,COUNTIFS($A$2:$A$3058,A7,$P$2:$P$3058,"OK")) -> 1 | S7: =IF(OR(A7="",P7="DUP",R7<2),"",IF(Q7=_xlfn.MINIFS($Q$2:$Q$3058,$A$2:$A$3058,A7,$P$2:$P$3058,"OK"),"KEEP","DROP")) | T7: =IF(A7="",1,0) -> 0 | U7: =IF(D7="",1,0) -> 0 | V7: =IF(E7="",1,0) -> 0 | W7: =IF(OR(H7<1,H7>10),1,0) -> 0 | X7: =IF(OR(I7<=0,I7>1500),1,0) -> 0 | Y7: =IF(J7>H7*I7,1,0) -> 0 | Z7: =IF(AND(N7<>"",OR(N7<1,N7>5)),1,0) -> 0 | AA7: =IF(AND(M7<>"",OR(M7<5,M7>180)),1,0) -> 0 | AB7: =IF(P7="DUP","Exact duplicate row",IF(T7=1,"Missing Order ID",IF(S7="DROP","Duplicate Order ID (less complete row)",IF(U7=1,"Missing Customer ID",IF(V7=1,"Missing Restaurant name",IF(W7=1,"Invalid/outlier quantity",IF(X7=1,"Invalid/outlier unit price",IF(Y7=1,"Discount greater than order value","")))))))) | AC7: =IF(AB7="","KEEP","DROP") -> KEEP | AD7: =IF(TRIM(F7)="",IFERROR(INDEX(Map_Tables!$I$4:$I$37,MATCH(TRIM(E7),Map_Tables!$G$4:$G$37,0)),""),IFERROR(INDEX(Map_Tables!$B$4:$B$18,MATCH(TRIM(F7),Map_Tables!$A$4:$A$18,0)),"CHECK")) -> Mumbai | AE7: =IF(TRIM(E7)="","",IFERROR(INDEX(Map_Tables!$H$4:$H$37,MATCH(TRIM(E7),Map_Tables!$G$4:$G$37,0)),"CHECK")) -> Mumbai Pizza Co | AF7: =IF(TRIM(K7)="","Unknown",IFERROR(INDEX(Map_Tables!$E$4:$E$15,MATCH(TRIM(K7),Map_Tables!$D$4:$D$15,0)),"CHECK")) -> Net Banking | AG7: =IF(LEFT(LOWER(TRIM(L7)),6)="cancel","Cancelled","Delivered") -> Delivered | AH7: =IF(ISNUMBER(SEARCH("/",B7)),DATE(VALUE(RIGHT(B7,4)),VALUE(MID(B7,4,2)),VALUE(LEFT(B7,2))),IF(MID(B7,5,1)="-",DATE(VALUE(LEFT(B7,4)),VALUE(MID(B7,6,2)),VALUE(RIGHT(B7,2))),DATE(VALUE(RIGHT(B7,4)),MATCH(MID(B7,4,3),{"Jan","Feb","Mar","Apr","May","Jun","Jul","Aug","Sep","Oct","Nov","Dec"},0),VALUE(LEFT(B7,2))))) -> 45992
A8: ORD10853 | B8: 2025-04-18 | C8: 12:48 | D8: C1006 | E8: Chaat Corner | F8: Delhi | G8: Street Food | H8: 1 | I8: 110 | J8: 0 | K8: Credit Card | L8: DELIVERED | M8: 34 | N8: 4 | O8: =A8&"|"&B8&"|"&C8&"|"&D8&"|"&E8&"|"&F8&"|"&G8&"|"&H8&"|"&I8&"|"&J8&"|"&K8&"|"&L8&"|"&M8&"|"&N8 -> ORD10853|2025-04-18|12:48|C1006|Chaat Corner|Delhi|Street Food|1|110|0|Credit Card|DELIVERED|34|4 | P8: =IF(COUNTIF($O$2:O8,O8)>1,"DUP","OK") -> OK | Q8: =COUNTBLANK(A8:N8) -> 0 | R8: =IF(A8="",0,COUNTIFS($A$2:$A$3058,A8,$P$2:$P$3058,"OK")) -> 1 | S8: =IF(OR(A8="",P8="DUP",R8<2),"",IF(Q8=_xlfn.MINIFS($Q$2:$Q$3058,$A$2:$A$3058,A8,$P$2:$P$3058,"OK"),"KEEP","DROP")) | T8: =IF(A8="",1,0) -> 0 | U8: =IF(D8="",1,0) -> 0 | V8: =IF(E8="",1,0) -> 0 | W8: =IF(OR(H8<1,H8>10),1,0) -> 0 | X8: =IF(OR(I8<=0,I8>1500),1,0) -> 0 | Y8: =IF(J8>H8*I8,1,0) -> 0 | Z8: =IF(AND(N8<>"",OR(N8<1,N8>5)),1,0) -> 0 | AA8: =IF(AND(M8<>"",OR(M8<5,M8>180)),1,0) -> 0 | AB8: =IF(P8="DUP","Exact duplicate row",IF(T8=1,"Missing Order ID",IF(S8="DROP","Duplicate Order ID (less complete row)",IF(U8=1,"Missing Customer ID",IF(V8=1,"Missing Restaurant name",IF(W8=1,"Invalid/outlier quantity",IF(X8=1,"Invalid/outlier unit price",IF(Y8=1,"Discount greater than order value","")))))))) | AC8: =IF(AB8="","KEEP","DROP") -> KEEP | AD8: =IF(TRIM(F8)="",IFERROR(INDEX(Map_Tables!$I$4:$I$37,MATCH(TRIM(E8),Map_Tables!$G$4:$G$37,0)),""),IFERROR(INDEX(Map_Tables!$B$4:$B$18,MATCH(TRIM(F8),Map_Tables!$A$4:$A$18,0)),"CHECK")) -> Delhi | AE8: =IF(TRIM(E8)="","",IFERROR(INDEX(Map_Tables!$H$4:$H$37,MATCH(TRIM(E8),Map_Tables!$G$4:$G$37,0)),"CHECK")) -> Chaat Corner | AF8: =IF(TRIM(K8)="","Unknown",IFERROR(INDEX(Map_Tables!$E$4:$E$15,MATCH(TRIM(K8),Map_Tables!$D$4:$D$15,0)),"CHECK")) -> Credit Card | AG8: =IF(LEFT(LOWER(TRIM(L8)),6)="cancel","Cancelled","Delivered") -> Delivered | AH8: =IF(ISNUMBER(SEARCH("/",B8)),DATE(VALUE(RIGHT(B8,4)),VALUE(MID(B8,4,2)),VALUE(LEFT(B8,2))),IF(MID(B8,5,1)="-",DATE(VALUE(LEFT(B8,4)),VALUE(MID(B8,6,2)),VALUE(RIGHT(B8,2))),DATE(VALUE(RIGHT(B8,4)),MATCH(MID(B8,4,3),{"Jan","Feb","Mar","Apr","May","Jun","Jul","Aug","Sep","Oct","Nov","Dec"},0),VALUE(LEFT(B8,2))))) -> 45765
A9: ORD12786 | B9: 2025-12-07 | C9: 10:20 | D9: C1030 | E9: Filter Coffee & Tiffin | F9: Chennai | G9: South Indian | H9: 2 | I9: 105 | J9: 84 | K9: UPI | L9: Delivered | M9: 37 | N9: 3 | O9: =A9&"|"&B9&"|"&C9&"|"&D9&"|"&E9&"|"&F9&"|"&G9&"|"&H9&"|"&I9&"|"&J9&"|"&K9&"|"&L9&"|"&M9&"|"&N9 -> ORD12786|2025-12-07|10:20|C1030|Filter Coffee & Tiffin|Chennai|South Indian|2|105|84|UPI|Delivered|37|3 | P9: =IF(COUNTIF($O$2:O9,O9)>1,"DUP","OK") -> OK | Q9: =COUNTBLANK(A9:N9) -> 0 | R9: =IF(A9="",0,COUNTIFS($A$2:$A$3058,A9,$P$2:$P$3058,"OK")) -> 1 | S9: =IF(OR(A9="",P9="DUP",R9<2),"",IF(Q9=_xlfn.MINIFS($Q$2:$Q$3058,$A$2:$A$3058,A9,$P$2:$P$3058,"OK"),"KEEP","DROP")) | T9: =IF(A9="",1,0) -> 0 | U9: =IF(D9="",1,0) -> 0 | V9: =IF(E9="",1,0) -> 0 | W9: =IF(OR(H9<1,H9>10),1,0) -> 0 | X9: =IF(OR(I9<=0,I9>1500),1,0) -> 0 | Y9: =IF(J9>H9*I9,1,0) -> 0 | Z9: =IF(AND(N9<>"",OR(N9<1,N9>5)),1,0) -> 0 | AA9: =IF(AND(M9<>"",OR(M9<5,M9>180)),1,0) -> 0 | AB9: =IF(P9="DUP","Exact duplicate row",IF(T9=1,"Missing Order ID",IF(S9="DROP","Duplicate Order ID (less complete row)",IF(U9=1,"Missing Customer ID",IF(V9=1,"Missing Restaurant name",IF(W9=1,"Invalid/outlier quantity",IF(X9=1,"Invalid/outlier unit price",IF(Y9=1,"Discount greater than order value","")))))))) | AC9: =IF(AB9="","KEEP","DROP") -> KEEP | AD9: =IF(TRIM(F9)="",IFERROR(INDEX(Map_Tables!$I$4:$I$37,MATCH(TRIM(E9),Map_Tables!$G$4:$G$37,0)),""),IFERROR(INDEX(Map_Tables!$B$4:$B$18,MATCH(TRIM(F9),Map_Tables!$A$4:$A$18,0)),"CHECK")) -> Chennai | AE9: =IF(TRIM(E9)="","",IFERROR(INDEX(Map_Tables!$H$4:$H$37,MATCH(TRIM(E9),Map_Tables!$G$4:$G$37,0)),"CHECK")) -> Filter Coffee & Tiffin | AF9: =IF(TRIM(K9)="","Unknown",IFERROR(INDEX(Map_Tables!$E$4:$E$15,MATCH(TRIM(K9),Map_Tables!$D$4:$D$15,0)),"CHECK")) -> UPI | AG9: =IF(LEFT(LOWER(TRIM(L9)),6)="cancel","Cancelled","Delivered") -> Delivered | AH9: =IF(ISNUMBER(SEARCH("/",B9)),DATE(VALUE(RIGHT(B9,4)),VALUE(MID(B9,4,2)),VALUE(LEFT(B9,2))),IF(MID(B9,5,1)="-",DATE(VALUE(LEFT(B9,4)),VALUE(MID(B9,6,2)),VALUE(RIGHT(B9,2))),DATE(VALUE(RIGHT(B9,4)),MATCH(MID(B9,4,3),{"Jan","Feb","Mar","Apr","May","Jun","Jul","Aug","Sep","Oct","Nov","Dec"},0),VALUE(LEFT(B9,2))))) -> 45998
A10: ORD12001 | B10: 2025-09-16 | C10: 21:36 | D10: C1488 | E10: Mumbai Pizza Co | F10: Mumbai | G10: Pizza | H10: 5 | I10: 295 | J10: 30 | K10: Upi | L10: Delivered | M10: 46 | N10: 3 | O10: =A10&"|"&B10&"|"&C10&"|"&D10&"|"&E10&"|"&F10&"|"&G10&"|"&H10&"|"&I10&"|"&J10&"|"&K10&"|"&L10&"|"&M10&"|"&N10 -> ORD12001|2025-09-16|21:36|C1488|Mumbai Pizza Co|Mumbai|Pizza|5|295|30|Upi|Delivered|46|3 | P10: =IF(COUNTIF($O$2:O10,O10)>1,"DUP","OK") -> OK | Q10: =COUNTBLANK(A10:N10) -> 0 | R10: =IF(A10="",0,COUNTIFS($A$2:$A$3058,A10,$P$2:$P$3058,"OK")) -> 1 | S10: =IF(OR(A10="",P10="DUP",R10<2),"",IF(Q10=_xlfn.MINIFS($Q$2:$Q$3058,$A$2:$A$3058,A10,$P$2:$P$3058,"OK"),"KEEP","DROP")) | T10: =IF(A10="",1,0) -> 0 | U10: =IF(D10="",1,0) -> 0 | V10: =IF(E10="",1,0) -> 0 | W10: =IF(OR(H10<1,H10>10),1,0) -> 0 | X10: =IF(OR(I10<=0,I10>1500),1,0) -> 0 | Y10: =IF(J10>H10*I10,1,0) -> 0 | Z10: =IF(AND(N10<>"",OR(N10<1,N10>5)),1,0) -> 0 | AA10: =IF(AND(M10<>"",OR(M10<5,M10>180)),1,0) -> 0 | AB10: =IF(P10="DUP","Exact duplicate row",IF(T10=1,"Missing Order ID",IF(S10="DROP","Duplicate Order ID (less complete row)",IF(U10=1,"Missing Customer ID",IF(V10=1,"Missing Restaurant name",IF(W10=1,"Invalid/outlier quantity",IF(X10=1,"Invalid/outlier unit price",IF(Y10=1,"Discount greater than order value","")))))))) | AC10: =IF(AB10="","KEEP","DROP") -> KEEP | AD10: =IF(TRIM(F10)="",IFERROR(INDEX(Map_Tables!$I$4:$I$37,MATCH(TRIM(E10),Map_Tables!$G$4:$G$37,0)),""),IFERROR(INDEX(Map_Tables!$B$4:$B$18,MATCH(TRIM(F10),Map_Tables!$A$4:$A$18,0)),"CHECK")) -> Mumbai | AE10: =IF(TRIM(E10)="","",IFERROR(INDEX(Map_Tables!$H$4:$H$37,MATCH(TRIM(E10),Map_Tables!$G$4:$G$37,0)),"CHECK")) -> Mumbai Pizza Co | AF10: =IF(TRIM(K10)="","Unknown",IFERROR(INDEX(Map_Tables!$E$4:$E$15,MATCH(TRIM(K10),Map_Tables!$D$4:$D$15,0)),"CHECK")) -> UPI | AG10: =IF(LEFT(LOWER(TRIM(L10)),6)="cancel","Cancelled","Delivered") -> Delivered | AH10: =IF(ISNUMBER(SEARCH("/",B10)),DATE(VALUE(RIGHT(B10,4)),VALUE(MID(B10,4,2)),VALUE(LEFT(B10,2))),IF(MID(B10,5,1)="-",DATE(VALUE(LEFT(B10,4)),VALUE(MID(B10,6,2)),VALUE(RIGHT(B10,2))),DATE(VALUE(RIGHT(B10,4)),MATCH(MID(B10,4,3),{"Jan","Feb","Mar","Apr","May","Jun","Jul","Aug","Sep","Oct","Nov","Dec"},0),VALUE(LEFT(B10,2))))) -> 45916
A11: ORD12725 | B11: 2025-11-30 | C11: 21:09 | D11: C0193 | E11: Curry Leaf Kitchen | F11: Mumbai | G11: North Indian | H11: 5 | I11: 220 | J11: 100 | K11: UPI | L11: Delivered | M11: 56 | N11: 3 | O11: =A11&"|"&B11&"|"&C11&"|"&D11&"|"&E11&"|"&F11&"|"&G11&"|"&H11&"|"&I11&"|"&J11&"|"&K11&"|"&L11&"|"&M11&"|"&N11 -> ORD12725|2025-11-30|21:09|C0193|Curry Leaf Kitchen|Mumbai|North Indian|5|220|100|UPI|Delivered|56|3 | P11: =IF(COUNTIF($O$2:O11,O11)>1,"DUP","OK") -> OK | Q11: =COUNTBLANK(A11:N11) -> 0 | R11: =IF(A11="",0,COUNTIFS($A$2:$A$3058,A11,$P$2:$P$3058,"OK")) -> 1 | S11: =IF(OR(A11="",P11="DUP",R11<2),"",IF(Q11=_xlfn.MINIFS($Q$2:$Q$3058,$A$2:$A$3058,A11,$P$2:$P$3058,"OK"),"KEEP","DROP")) | T11: =IF(A11="",1,0) -> 0 | U11: =IF(D11="",1,0) -> 0 | V11: =IF(E11="",1,0) -> 0 | W11: =IF(OR(H11<1,H11>10),1,0) -> 0 | X11: =IF(OR(I11<=0,I11>1500),1,0) -> 0 | Y11: =IF(J11>H11*I11,1,0) -> 0 | Z11: =IF(AND(N11<>"",OR(N11<1,N11>5)),1,0) -> 0 | AA11: =IF(AND(M11<>"",OR(M11<5,M11>180)),1,0) -> 0 | AB11: =IF(P11="DUP","Exact duplicate row",IF(T11=1,"Missing Order ID",IF(S11="DROP","Duplicate Order ID (less complete row)",IF(U11=1,"Missing Customer ID",IF(V11=1,"Missing Restaurant name",IF(W11=1,"Invalid/outlier quantity",IF(X11=1,"Invalid/outlier unit price",IF(Y11=1,"Discount greater than order value","")))))))) | AC11: =IF(AB11="","KEEP","DROP") -> KEEP | AD11: =IF(TRIM(F11)="",IFERROR(INDEX(Map_Tables!$I$4:$I$37,MATCH(TRIM(E11),Map_Tables!$G$4:$G$37,0)),""),IFERROR(INDEX(Map_Tables!$B$4:$B$18,MATCH(TRIM(F11),Map_Tables!$A$4:$A$18,0)),"CHECK")) -> Mumbai | AE11: =IF(TRIM(E11)="","",IFERROR(INDEX(Map_Tables!$H$4:$H$37,MATCH(TRIM(E11),Map_Tables!$G$4:$G$37,0)),"CHECK")) -> Curry Leaf Kitchen | AF11: =IF(TRIM(K11)="","Unknown",IFERROR(INDEX(Map_Tables!$E$4:$E$15,MATCH(TRIM(K11),Map_Tables!$D$4:$D$15,0)),"CHECK")) -> UPI | AG11: =IF(LEFT(LOWER(TRIM(L11)),6)="cancel","Cancelled","Delivered") -> Delivered | AH11: =IF(ISNUMBER(SEARCH("/",B11)),DATE(VALUE(RIGHT(B11,4)),VALUE(MID(B11,4,2)),VALUE(LEFT(B11,2))),IF(MID(B11,5,1)="-",DATE(VALUE(LEFT(B11,4)),VALUE(MID(B11,6,2)),VALUE(RIGHT(B11,2))),DATE(VALUE(RIGHT(B11,4)),MATCH(MID(B11,4,3),{"Jan","Feb","Mar","Apr","May","Jun","Jul","Aug","Sep","Oct","Nov","Dec"},0),VALUE(LEFT(B11,2))))) -> 45991
A12: ORD10430 | B12: 2025-02-27 | C12: 19:26 | D12: C1390 | E12: Chaat Corner | F12: Delhi | G12: Street Food | H12: 5 | I12: 105 | J12: 0 | K12: UPI | L12: Cancelled | O12: =A12&"|"&B12&"|"&C12&"|"&D12&"|"&E12&"|"&F12&"|"&G12&"|"&H12&"|"&I12&"|"&J12&"|"&K12&"|"&L12&"|"&M12&"|"&N12 -> ORD10430|2025-02-27|19:26|C1390|Chaat Corner|Delhi|Street Food|5|105|0|UPI|Cancelled|| | P12: =IF(COUNTIF($O$2:O12,O12)>1,"DUP","OK") -> OK | Q12: =COUNTBLANK(A12:N12) -> 2 | R12: =IF(A12="",0,COUNTIFS($A$2:$A$3058,A12,$P$2:$P$3058,"OK")) -> 1 | S12: =IF(OR(A12="",P12="DUP",R12<2),"",IF(Q12=_xlfn.MINIFS($Q$2:$Q$3058,$A$2:$A$3058,A12,$P$2:$P$3058,"OK"),"KEEP","DROP")) | T12: =IF(A12="",1,0) -> 0 | U12: =IF(D12="",1,0) -> 0 | V12: =IF(E12="",1,0) -> 0 | W12: =IF(OR(H12<1,H12>10),1,0) -> 0 | X12: =IF(OR(I12<=0,I12>1500),1,0) -> 0 | Y12: =IF(J12>H12*I12,1,0) -> 0 | Z12: =IF(AND(N12<>"",OR(N12<1,N12>5)),1,0) -> 0 | AA12: =IF(AND(M12<>"",OR(M12<5,M12>180)),1,0) -> 0 | AB12: =IF(P12="DUP","Exact duplicate row",IF(T12=1,"Missing Order ID",IF(S12="DROP","Duplicate Order ID (less complete row)",IF(U12=1,"Missing Customer ID",IF(V12=1,"Missing Restaurant name",IF(W12=1,"Invalid/outlier quantity",IF(X12=1,"Invalid/outlier unit price",IF(Y12=1,"Discount greater than order value","")))))))) | AC12: =IF(AB12="","KEEP","DROP") -> KEEP | AD12: =IF(TRIM(F12)="",IFERROR(INDEX(Map_Tables!$I$4:$I$37,MATCH(TRIM(E12),Map_Tables!$G$4:$G$37,0)),""),IFERROR(INDEX(Map_Tables!$B$4:$B$18,MATCH(TRIM(F12),Map_Tables!$A$4:$A$18,0)),"CHECK")) -> Delhi | AE12: =IF(TRIM(E12)="","",IFERROR(INDEX(Map_Tables!$H$4:$H$37,MATCH(TRIM(E12),Map_Tables!$G$4:$G$37,0)),"CHECK")) -> Chaat Corner | AF12: =IF(TRIM(K12)="","Unknown",IFERROR(INDEX(Map_Tables!$E$4:$E$15,MATCH(TRIM(K12),Map_Tables!$D$4:$D$15,0)),"CHECK")) -> UPI | AG12: =IF(LEFT(LOWER(TRIM(L12)),6)="cancel","Cancelled","Delivered") -> Cancelled | AH12: =IF(ISNUMBER(SEARCH("/",B12)),DATE(VALUE(RIGHT(B12,4)),VALUE(MID(B12,4,2)),VALUE(LEFT(B12,2))),IF(MID(B12,5,1)="-",DATE(VALUE(LEFT(B12,4)),VALUE(MID(B12,6,2)),VALUE(RIGHT(B12,2))),DATE(VALUE(RIGHT(B12,4)),MATCH(MID(B12,4,3),{"Jan","Feb","Mar","Apr","May","Jun","Jul","Aug","Sep","Oct","Nov","Dec"},0),VALUE(LEFT(B12,2))))) -> 45715
A13: ORD12148 | B13: 2025-10-02 | C13: 11:59 | D13: C1117 | E13: Maratha Thali House | F13: Pune | G13: North Indian | H13: 4 | I13: 285 | J13: 150 | K13: Credit Card | L13: Delivered | M13: 33 | N13: 5 | O13: =A13&"|"&B13&"|"&C13&"|"&D13&"|"&E13&"|"&F13&"|"&G13&"|"&H13&"|"&I13&"|"&J13&"|"&K13&"|"&L13&"|"&M13&"|"&N13 -> ORD12148|2025-10-02|11:59|C1117|Maratha Thali House|Pune|North Indian|4|285|150|Credit Card|Delivered|33|5 | P13: =IF(COUNTIF($O$2:O13,O13)>1,"DUP","OK") -> OK | Q13: =COUNTBLANK(A13:N13) -> 0 | R13: =IF(A13="",0,COUNTIFS($A$2:$A$3058,A13,$P$2:$P$3058,"OK")) -> 1 | S13: =IF(OR(A13="",P13="DUP",R13<2),"",IF(Q13=_xlfn.MINIFS($Q$2:$Q$3058,$A$2:$A$3058,A13,$P$2:$P$3058,"OK"),"KEEP","DROP")) | T13: =IF(A13="",1,0) -> 0 | U13: =IF(D13="",1,0) -> 0 | V13: =IF(E13="",1,0) -> 0 | W13: =IF(OR(H13<1,H13>10),1,0) -> 0 | X13: =IF(OR(I13<=0,I13>1500),1,0) -> 0 | Y13: =IF(J13>H13*I13,1,0) -> 0 | Z13: =IF(AND(N13<>"",OR(N13<1,N13>5)),1,0) -> 0 | AA13: =IF(AND(M13<>"",OR(M13<5,M13>180)),1,0) -> 0 | AB13: =IF(P13="DUP","Exact duplicate row",IF(T13=1,"Missing Order ID",IF(S13="DROP","Duplicate Order ID (less complete row)",IF(U13=1,"Missing Customer ID",IF(V13=1,"Missing Restaurant name",IF(W13=1,"Invalid/outlier quantity",IF(X13=1,"Invalid/outlier unit price",IF(Y13=1,"Discount greater than order value","")))))))) | AC13: =IF(AB13="","KEEP","DROP") -> KEEP | AD13: =IF(TRIM(F13)="",IFERROR(INDEX(Map_Tables!$I$4:$I$37,MATCH(TRIM(E13),Map_Tables!$G$4:$G$37,0)),""),IFERROR(INDEX(Map_Tables!$B$4:$B$18,MATCH(TRIM(F13),Map_Tables!$A$4:$A$18,0)),"CHECK")) -> Pune | AE13: =IF(TRIM(E13)="","",IFERROR(INDEX(Map_Tables!$H$4:$H$37,MATCH(TRIM(E13),Map_Tables!$G$4:$G$37,0)),"CHECK")) -> Maratha Thali House | AF13: =IF(TRIM(K13)="","Unknown",IFERROR(INDEX(Map_Tables!$E$4:$E$15,MATCH(TRIM(K13),Map_Tables!$D$4:$D$15,0)),"CHECK")) -> Credit Card | AG13: =IF(LEFT(LOWER(TRIM(L13)),6)="cancel","Cancelled","Delivered") -> Delivered | AH13: =IF(ISNUMBER(SEARCH("/",B13)),DATE(VALUE(RIGHT(B13,4)),VALUE(MID(B13,4,2)),VALUE(LEFT(B13,2))),IF(MID(B13,5,1)="-",DATE(VALUE(LEFT(B13,4)),VALUE(MID(B13,6,2)),VALUE(RIGHT(B13,2))),DATE(VALUE(RIGHT(B13,4)),MATCH(MID(B13,4,3),{"Jan","Feb","Mar","Apr","May","Jun","Jul","Aug","Sep","Oct","Nov","Dec"},0),VALUE(LEFT(B13,2))))) -> 45932
A14: ORD10728 | B14: 2025-04-03 | C14: 13:09 | D14: C1478 | E14: Bengal Bites | F14: Kolkata | G14: Street Food | H14: 5 | I14: 110 | J14: 20 | K14: Credit Card | L14: Cancelled | O14: =A14&"|"&B14&"|"&C14&"|"&D14&"|"&E14&"|"&F14&"|"&G14&"|"&H14&"|"&I14&"|"&J14&"|"&K14&"|"&L14&"|"&M14&"|"&N14 -> ORD10728|2025-04-03|13:09|C1478|Bengal Bites|Kolkata|Street Food|5|110|20|Credit Card|Cancelled|| | P14: =IF(COUNTIF($O$2:O14,O14)>1,"DUP","OK") -> OK | Q14: =COUNTBLANK(A14:N14) -> 2 | R14: =IF(A14="",0,COUNTIFS($A$2:$A$3058,A14,$P$2:$P$3058,"OK")) -> 1 | S14: =IF(OR(A14="",P14="DUP",R14<2),"",IF(Q14=_xlfn.MINIFS($Q$2:$Q$3058,$A$2:$A$3058,A14,$P$2:$P$3058,"OK"),"KEEP","DROP")) | T14: =IF(A14="",1,0) -> 0 | U14: =IF(D14="",1,0) -> 0 | V14: =IF(E14="",1,0) -> 0 | W14: =IF(OR(H14<1,H14>10),1,0) -> 0 | X14: =IF(OR(I14<=0,I14>1500),1,0) -> 0 | Y14: =IF(J14>H14*I14,1,0) -> 0 | Z14: =IF(AND(N14<>"",OR(N14<1,N14>5)),1,0) -> 0 | AA14: =IF(AND(M14<>"",OR(M14<5,M14>180)),1,0) -> 0 | AB14: =IF(P14="DUP","Exact duplicate row",IF(T14=1,"Missing Order ID",IF(S14="DROP","Duplicate Order ID (less complete row)",IF(U14=1,"Missing Customer ID",IF(V14=1,"Missing Restaurant name",IF(W14=1,"Invalid/outlier quantity",IF(X14=1,"Invalid/outlier unit price",IF(Y14=1,"Discount greater than order value","")))))))) | AC14: =IF(AB14="","KEEP","DROP") -> KEEP | AD14: =IF(TRIM(F14)="",IFERROR(INDEX(Map_Tables!$I$4:$I$37,MATCH(TRIM(E14),Map_Tables!$G$4:$G$37,0)),""),IFERROR(INDEX(Map_Tables!$B$4:$B$18,MATCH(TRIM(F14),Map_Tables!$A$4:$A$18,0)),"CHECK")) -> Kolkata | AE14: =IF(TRIM(E14)="","",IFERROR(INDEX(Map_Tables!$H$4:$H$37,MATCH(TRIM(E14),Map_Tables!$G$4:$G$37,0)),"CHECK")) -> Bengal Bites | AF14: =IF(TRIM(K14)="","Unknown",IFERROR(INDEX(Map_Tables!$E$4:$E$15,MATCH(TRIM(K14),Map_Tables!$D$4:$D$15,0)),"CHECK")) -> Credit Card | AG14: =IF(LEFT(LOWER(TRIM(L14)),6)="cancel","Cancelled","Delivered") -> Cancelled | AH14: =IF(ISNUMBER(SEARCH("/",B14)),DATE(VALUE(RIGHT(B14,4)),VALUE(MID(B14,4,2)),VALUE(LEFT(B14,2))),IF(MID(B14,5,1)="-",DATE(VALUE(LEFT(B14,4)),VALUE(MID(B14,6,2)),VALUE(RIGHT(B14,2))),DATE(VALUE(RIGHT(B14,4)),MATCH(MID(B14,4,3),{"Jan","Feb","Mar","Apr","May","Jun","Jul","Aug","Sep","Oct","Nov","Dec"},0),VALUE(LEFT(B14,2))))) -> 45750
A15: ORD10455 | B15: 2025-03-02 | C15: 14:00 | D15: C0969 | E15: Burger Barn | F15: Delhi | G15: burgers | H15: 1 | I15: 225 | J15: 0 | K15: UPI | L15: Delivered | M15: 36 | N15: 4 | O15: =A15&"|"&B15&"|"&C15&"|"&D15&"|"&E15&"|"&F15&"|"&G15&"|"&H15&"|"&I15&"|"&J15&"|"&K15&"|"&L15&"|"&M15&"|"&N15 -> ORD10455|2025-03-02|14:00|C0969|Burger Barn|Delhi|burgers|1|225|0|UPI|Delivered|36|4 | P15: =IF(COUNTIF($O$2:O15,O15)>1,"DUP","OK") -> OK | Q15: =COUNTBLANK(A15:N15) -> 0 | R15: =IF(A15="",0,COUNTIFS($A$2:$A$3058,A15,$P$2:$P$3058,"OK")) -> 1 | S15: =IF(OR(A15="",P15="DUP",R15<2),"",IF(Q15=_xlfn.MINIFS($Q$2:$Q$3058,$A$2:$A$3058,A15,$P$2:$P$3058,"OK"),"KEEP","DROP")) | T15: =IF(A15="",1,0) -> 0 | U15: =IF(D15="",1,0) -> 0 | V15: =IF(E15="",1,0) -> 0 | W15: =IF(OR(H15<1,H15>10),1,0) -> 0 | X15: =IF(OR(I15<=0,I15>1500),1,0) -> 0 | Y15: =IF(J15>H15*I15,1,0) -> 0 | Z15: =IF(AND(N15<>"",OR(N15<1,N15>5)),1,0) -> 0 | AA15: =IF(AND(M15<>"",OR(M15<5,M15>180)),1,0) -> 0 | AB15: =IF(P15="DUP","Exact duplicate row",IF(T15=1,"Missing Order ID",IF(S15="DROP","Duplicate Order ID (less complete row)",IF(U15=1,"Missing Customer ID",IF(V15=1,"Missing Restaurant name",IF(W15=1,"Invalid/outlier quantity",IF(X15=1,"Invalid/outlier unit price",IF(Y15=1,"Discount greater than order value","")))))))) | AC15: =IF(AB15="","KEEP","DROP") -> KEEP | AD15: =IF(TRIM(F15)="",IFERROR(INDEX(Map_Tables!$I$4:$I$37,MATCH(TRIM(E15),Map_Tables!$G$4:$G$37,0)),""),IFERROR(INDEX(Map_Tables!$B$4:$B$18,MATCH(TRIM(F15),Map_Tables!$A$4:$A$18,0)),"CHECK")) -> Delhi | AE15: =IF(TRIM(E15)="","",IFERROR(INDEX(Map_Tables!$H$4:$H$37,MATCH(TRIM(E15),Map_Tables!$G$4:$G$37,0)),"CHECK")) -> Burger Barn | AF15: =IF(TRIM(K15)="","Unknown",IFERROR(INDEX(Map_Tables!$E$4:$E$15,MATCH(TRIM(K15),Map_Tables!$D$4:$D$15,0)),"CHECK")) -> UPI | AG15: =IF(LEFT(LOWER(TRIM(L15)),6)="cancel","Cancelled","Delivered") -> Delivered | AH15: =IF(ISNUMBER(SEARCH("/",B15)),DATE(VALUE(RIGHT(B15,4)),VALUE(MID(B15,4,2)),VALUE(LEFT(B15,2))),IF(MID(B15,5,1)="-",DATE(VALUE(LEFT(B15,4)),VALUE(MID(B15,6,2)),VALUE(RIGHT(B15,2))),DATE(VALUE(RIGHT(B15,4)),MATCH(MID(B15,4,3),{"Jan","Feb","Mar","Apr","May","Jun","Jul","Aug","Sep","Oct","Nov","Dec"},0),VALUE(LEFT(B15,2))))) -> 45718
A16: ORD10741 | B16: 2025-04-04 | C16: 20:58 | D16: C0821 | E16: Mumbai Pizza Co | F16: Mumbai | G16: Pizza | H16: 1 | I16: 255 | J16: 75 | K16: UPI | L16: Delivered | M16: 53 | N16: 2 | O16: =A16&"|"&B16&"|"&C16&"|"&D16&"|"&E16&"|"&F16&"|"&G16&"|"&H16&"|"&I16&"|"&J16&"|"&K16&"|"&L16&"|"&M16&"|"&N16 -> ORD10741|2025-04-04|20:58|C0821|Mumbai Pizza Co|Mumbai|Pizza|1|255|75|UPI|Delivered|53|2 | P16: =IF(COUNTIF($O$2:O16,O16)>1,"DUP","OK") -> OK | Q16: =COUNTBLANK(A16:N16) -> 0 | R16: =IF(A16="",0,COUNTIFS($A$2:$A$3058,A16,$P$2:$P$3058,"OK")) -> 1 | S16: =IF(OR(A16="",P16="DUP",R16<2),"",IF(Q16=_xlfn.MINIFS($Q$2:$Q$3058,$A$2:$A$3058,A16,$P$2:$P$3058,"OK"),"KEEP","DROP")) | T16: =IF(A16="",1,0) -> 0 | U16: =IF(D16="",1,0) -> 0 | V16: =IF(E16="",1,0) -> 0 | W16: =IF(OR(H16<1,H16>10),1,0) -> 0 | X16: =IF(OR(I16<=0,I16>1500),1,0) -> 0 | Y16: =IF(J16>H16*I16,1,0) -> 0 | Z16: =IF(AND(N16<>"",OR(N16<1,N16>5)),1,0) -> 0 | AA16: =IF(AND(M16<>"",OR(M16<5,M16>180)),1,0) -> 0 | AB16: =IF(P16="DUP","Exact duplicate row",IF(T16=1,"Missing Order ID",IF(S16="DROP","Duplicate Order ID (less complete row)",IF(U16=1,"Missing Customer ID",IF(V16=1,"Missing Restaurant name",IF(W16=1,"Invalid/outlier quantity",IF(X16=1,"Invalid/outlier unit price",IF(Y16=1,"Discount greater than order value","")))))))) | AC16: =IF(AB16="","KEEP","DROP") -> KEEP | AD16: =IF(TRIM(F16)="",IFERROR(INDEX(Map_Tables!$I$4:$I$37,MATCH(TRIM(E16),Map_Tables!$G$4:$G$37,0)),""),IFERROR(INDEX(Map_Tables!$B$4:$B$18,MATCH(TRIM(F16),Map_Tables!$A$4:$A$18,0)),"CHECK")) -> Mumbai | AE16: =IF(TRIM(E16)="","",IFERROR(INDEX(Map_Tables!$H$4:$H$37,MATCH(TRIM(E16),Map_Tables!$G$4:$G$37,0)),"CHECK")) -> Mumbai Pizza Co | AF16: =IF(TRIM(K16)="","Unknown",IFERROR(INDEX(Map_Tables!$E$4:$E$15,MATCH(TRIM(K16),Map_Tables!$D$4:$D$15,0)),"CHECK")) -> UPI | AG16: =IF(LEFT(LOWER(TRIM(L16)),6)="cancel","Cancelled","Delivered") -> Delivered | AH16: =IF(ISNUMBER(SEARCH("/",B16)),DATE(VALUE(RIGHT(B16,4)),VALUE(MID(B16,4,2)),VALUE(LEFT(B16,2))),IF(MID(B16,5,1)="-",DATE(VALUE(LEFT(B16,4)),VALUE(MID(B16,6,2)),VALUE(RIGHT(B16,2))),DATE(VALUE(RIGHT(B16,4)),MATCH(MID(B16,4,3),{"Jan","Feb","Mar","Apr","May","Jun","Jul","Aug","Sep","Oct","Nov","Dec"},0),VALUE(LEFT(B16,2))))) -> 45751
A17: ORD10363 | B17: 2025-02-17 | C17: 20:24 | D17: C0392 | E17: Burger Barn | F17: Delhi | G17: Burgers | H17: 2 | I17: 125 | J17: 100 | K17: UPI | L17: Delivered | M17: 33 | N17: 3 | O17: =A17&"|"&B17&"|"&C17&"|"&D17&"|"&E17&"|"&F17&"|"&G17&"|"&H17&"|"&I17&"|"&J17&"|"&K17&"|"&L17&"|"&M17&"|"&N17 -> ORD10363|2025-02-17|20:24|C0392| Burger Barn|Delhi|Burgers|2|125|100|UPI|Delivered|33|3 | P17: =IF(COUNTIF($O$2:O17,O17)>1,"DUP","OK") -> OK | Q17: =COUNTBLANK(A17:N17) -> 0 | R17: =IF(A17="",0,COUNTIFS($A$2:$A$3058,A17,$P$2:$P$3058,"OK")) -> 1 | S17: =IF(OR(A17="",P17="DUP",R17<2),"",IF(Q17=_xlfn.MINIFS($Q$2:$Q$3058,$A$2:$A$3058,A17,$P$2:$P$3058,"OK"),"KEEP","DROP")) | T17: =IF(A17="",1,0) -> 0 | U17: =IF(D17="",1,0) -> 0 | V17: =IF(E17="",1,0) -> 0 | W17: =IF(OR(H17<1,H17>10),1,0) -> 0 | X17: =IF(OR(I17<=0,I17>1500),1,0) -> 0 | Y17: =IF(J17>H17*I17,1,0) -> 0 | Z17: =IF(AND(N17<>"",OR(N17<1,N17>5)),1,0) -> 0 | AA17: =IF(AND(M17<>"",OR(M17<5,M17>180)),1,0) -> 0 | AB17: =IF(P17="DUP","Exact duplicate row",IF(T17=1,"Missing Order ID",IF(S17="DROP","Duplicate Order ID (less complete row)",IF(U17=1,"Missing Customer ID",IF(V17=1,"Missing Restaurant name",IF(W17=1,"Invalid/outlier quantity",IF(X17=1,"Invalid/outlier unit price",IF(Y17=1,"Discount greater than order value","")))))))) | AC17: =IF(AB17="","KEEP","DROP") -> KEEP | AD17: =IF(TRIM(F17)="",IFERROR(INDEX(Map_Tables!$I$4:$I$37,MATCH(TRIM(E17),Map_Tables!$G$4:$G$37,0)),""),IFERROR(INDEX(Map_Tables!$B$4:$B$18,MATCH(TRIM(F17),Map_Tables!$A$4:$A$18,0)),"CHECK")) -> Delhi | AE17: =IF(TRIM(E17)="","",IFERROR(INDEX(Map_Tables!$H$4:$H$37,MATCH(TRIM(E17),Map_Tables!$G$4:$G$37,0)),"CHECK")) -> Burger Barn | AF17: =IF(TRIM(K17)="","Unknown",IFERROR(INDEX(Map_Tables!$E$4:$E$15,MATCH(TRIM(K17),Map_Tables!$D$4:$D$15,0)),"CHECK")) -> UPI | AG17: =IF(LEFT(LOWER(TRIM(L17)),6)="cancel","Cancelled","Delivered") -> Delivered | AH17: =IF(ISNUMBER(SEARCH("/",B17)),DATE(VALUE(RIGHT(B17,4)),VALUE(MID(B17,4,2)),VALUE(LEFT(B17,2))),IF(MID(B17,5,1)="-",DATE(VALUE(LEFT(B17,4)),VALUE(MID(B17,6,2)),VALUE(RIGHT(B17,2))),DATE(VALUE(RIGHT(B17,4)),MATCH(MID(B17,4,3),{"Jan","Feb","Mar","Apr","May","Jun","Jul","Aug","Sep","Oct","Nov","Dec"},0),VALUE(LEFT(B17,2))))) -> 45705
A18: ORD11338 | B18: 2025-06-22 | C18: 11:22 | D18: C1445 | E18: Pune Burger Hub | F18: Pune | G18: Burgers | H18: 4 | I18: 235 | J18: 0 | K18: UPI | L18: Delivered | M18: 30 | N18: 5 | O18: =A18&"|"&B18&"|"&C18&"|"&D18&"|"&E18&"|"&F18&"|"&G18&"|"&H18&"|"&I18&"|"&J18&"|"&K18&"|"&L18&"|"&M18&"|"&N18 -> ORD11338|2025-06-22|11:22|C1445| Pune Burger Hub|Pune|Burgers|4|235|0|UPI|Delivered|30|5 | P18: =IF(COUNTIF($O$2:O18,O18)>1,"DUP","OK") -> OK | Q18: =COUNTBLANK(A18:N18) -> 0 | R18: =IF(A18="",0,COUNTIFS($A$2:$A$3058,A18,$P$2:$P$3058,"OK")) -> 1 | S18: =IF(OR(A18="",P18="DUP",R18<2),"",IF(Q18=_xlfn.MINIFS($Q$2:$Q$3058,$A$2:$A$3058,A18,$P$2:$P$3058,"OK"),"KEEP","DROP")) | T18: =IF(A18="",1,0) -> 0 | U18: =IF(D18="",1,0) -> 0 | V18: =IF(E18="",1,0) -> 0 | W18: =IF(OR(H18<1,H18>10),1,0) -> 0 | X18: =IF(OR(I18<=0,I18>1500),1,0) -> 0 | Y18: =IF(J18>H18*I18,1,0) -> 0 | Z18: =IF(AND(N18<>"",OR(N18<1,N18>5)),1,0) -> 0 | AA18: =IF(AND(M18<>"",OR(M18<5,M18>180)),1,0) -> 0 | AB18: =IF(P18="DUP","Exact duplicate row",IF(T18=1,"Missing Order ID",IF(S18="DROP","Duplicate Order ID (less complete row)",IF(U18=1,"Missing Customer ID",IF(V18=1,"Missing Restaurant name",IF(W18=1,"Invalid/outlier quantity",IF(X18=1,"Invalid/outlier unit price",IF(Y18=1,"Discount greater than order value","")))))))) | AC18: =IF(AB18="","KEEP","DROP") -> KEEP | AD18: =IF(TRIM(F18)="",IFERROR(INDEX(Map_Tables!$I$4:$I$37,MATCH(TRIM(E18),Map_Tables!$G$4:$G$37,0)),""),IFERROR(INDEX(Map_Tables!$B$4:$B$18,MATCH(TRIM(F18),Map_Tables!$A$4:$A$18,0)),"CHECK")) -> Pune | AE18: =IF(TRIM(E18)="","",IFERROR(INDEX(Map_Tables!$H$4:$H$37,MATCH(TRIM(E18),Map_Tables!$G$4:$G$37,0)),"CHECK")) -> Pune Burger Hub | AF18: =IF(TRIM(K18)="","Unknown",IFERROR(INDEX(Map_Tables!$E$4:$E$15,MATCH(TRIM(K18),Map_Tables!$D$4:$D$15,0)),"CHECK")) -> UPI | AG18: =IF(LEFT(LOWER(TRIM(L18)),6)="cancel","Cancelled","Delivered") -> Delivered | AH18: =IF(ISNUMBER(SEARCH("/",B18)),DATE(VALUE(RIGHT(B18,4)),VALUE(MID(B18,4,2)),VALUE(LEFT(B18,2))),IF(MID(B18,5,1)="-",DATE(VALUE(LEFT(B18,4)),VALUE(MID(B18,6,2)),VALUE(RIGHT(B18,2))),DATE(VALUE(RIGHT(B18,4)),MATCH(MID(B18,4,3),{"Jan","Feb","Mar","Apr","May","Jun","Jul","Aug","Sep","Oct","Nov","Dec"},0),VALUE(LEFT(B18,2))))) -> 45830
A19: ORD11217 | B19: 2025-06-03 | C19: 19:16 | D19: C1418 | E19: Wok & Roll | F19: Bengaluru | G19: Chinese | H19: 3 | I19: 210 | J19: 0 | K19: UPI | L19: Delivered | M19: 49 | N19: 3 | O19: =A19&"|"&B19&"|"&C19&"|"&D19&"|"&E19&"|"&F19&"|"&G19&"|"&H19&"|"&I19&"|"&J19&"|"&K19&"|"&L19&"|"&M19&"|"&N19 -> ORD11217|2025-06-03|19:16|C1418|Wok & Roll|Bengaluru|Chinese|3|210|0|UPI|Delivered|49|3 | P19: =IF(COUNTIF($O$2:O19,O19)>1,"DUP","OK") -> OK | Q19: =COUNTBLANK(A19:N19) -> 0 | R19: =IF(A19="",0,COUNTIFS($A$2:$A$3058,A19,$P$2:$P$3058,"OK")) -> 1 | S19: =IF(OR(A19="",P19="DUP",R19<2),"",IF(Q19=_xlfn.MINIFS($Q$2:$Q$3058,$A$2:$A$3058,A19,$P$2:$P$3058,"OK"),"KEEP","DROP")) | T19: =IF(A19="",1,0) -> 0 | U19: =IF(D19="",1,0) -> 0 | V19: =IF(E19="",1,0) -> 0 | W19: =IF(OR(H19<1,H19>10),1,0) -> 0 | X19: =IF(OR(I19<=0,I19>1500),1,0) -> 0 | Y19: =IF(J19>H19*I19,1,0) -> 0 | Z19: =IF(AND(N19<>"",OR(N19<1,N19>5)),1,0) -> 0 | AA19: =IF(AND(M19<>"",OR(M19<5,M19>180)),1,0) -> 0 | AB19: =IF(P19="DUP","Exact duplicate row",IF(T19=1,"Missing Order ID",IF(S19="DROP","Duplicate Order ID (less complete row)",IF(U19=1,"Missing Customer ID",IF(V19=1,"Missing Restaurant name",IF(W19=1,"Invalid/outlier quantity",IF(X19=1,"Invalid/outlier unit price",IF(Y19=1,"Discount greater than order value","")))))))) | AC19: =IF(AB19="","KEEP","DROP") -> KEEP | AD19: =IF(TRIM(F19)="",IFERROR(INDEX(Map_Tables!$I$4:$I$37,MATCH(TRIM(E19),Map_Tables!$G$4:$G$37,0)),""),IFERROR(INDEX(Map_Tables!$B$4:$B$18,MATCH(TRIM(F19),Map_Tables!$A$4:$A$18,0)),"CHECK")) -> Bengaluru | AE19: =IF(TRIM(E19)="","",IFERROR(INDEX(Map_Tables!$H$4:$H$37,MATCH(TRIM(E19),Map_Tables!$G$4:$G$37,0)),"CHECK")) -> Wok & Roll | AF19: =IF(TRIM(K19)="","Unknown",IFERROR(INDEX(Map_Tables!$E$4:$E$15,MATCH(TRIM(K19),Map_Tables!$D$4:$D$15,0)),"CHECK")) -> UPI | AG19: =IF(LEFT(LOWER(TRIM(L19)),6)="cancel","Cancelled","Delivered") -> Delivered | AH19: =IF(ISNUMBER(SEARCH("/",B19)),DATE(VALUE(RIGHT(B19,4)),VALUE(MID(B19,4,2)),VALUE(LEFT(B19,2))),IF(MID(B19,5,1)="-",DATE(VALUE(LEFT(B19,4)),VALUE(MID(B19,6,2)),VALUE(RIGHT(B19,2))),DATE(VALUE(RIGHT(B19,4)),MATCH(MID(B19,4,3),{"Jan","Feb","Mar","Apr","May","Jun","Jul","Aug","Sep","Oct","Nov","Dec"},0),VALUE(LEFT(B19,2))))) -> 45811
A20: ORD10581 | B20: 2025-03-15 | C20: 14:01 | D20: C1344 | E20: Pav Bhaji Point | F20: Mumbai | G20: Street Food | H20: 3 | I20: 145 | J20: 150 | K20: Wallet | L20: Delivered | M20: 42 | N20: 5 | O20: =A20&"|"&B20&"|"&C20&"|"&D20&"|"&E20&"|"&F20&"|"&G20&"|"&H20&"|"&I20&"|"&J20&"|"&K20&"|"&L20&"|"&M20&"|"&N20 -> ORD10581|2025-03-15|14:01|C1344|Pav Bhaji Point|Mumbai|Street Food|3|145|150|Wallet|Delivered|42|5 | P20: =IF(COUNTIF($O$2:O20,O20)>1,"DUP","OK") -> OK | Q20: =COUNTBLANK(A20:N20) -> 0 | R20: =IF(A20="",0,COUNTIFS($A$2:$A$3058,A20,$P$2:$P$3058,"OK")) -> 1 | S20: =IF(OR(A20="",P20="DUP",R20<2),"",IF(Q20=_xlfn.MINIFS($Q$2:$Q$3058,$A$2:$A$3058,A20,$P$2:$P$3058,"OK"),"KEEP","DROP")) | T20: =IF(A20="",1,0) -> 0 | U20: =IF(D20="",1,0) -> 0 | V20: =IF(E20="",1,0) -> 0 | W20: =IF(OR(H20<1,H20>10),1,0) -> 0 | X20: =IF(OR(I20<=0,I20>1500),1,0) -> 0 | Y20: =IF(J20>H20*I20,1,0) -> 0 | Z20: =IF(AND(N20<>"",OR(N20<1,N20>5)),1,0) -> 0 | AA20: =IF(AND(M20<>"",OR(M20<5,M20>180)),1,0) -> 0 | AB20: =IF(P20="DUP","Exact duplicate row",IF(T20=1,"Missing Order ID",IF(S20="DROP","Duplicate Order ID (less complete row)",IF(U20=1,"Missing Customer ID",IF(V20=1,"Missing Restaurant name",IF(W20=1,"Invalid/outlier quantity",IF(X20=1,"Invalid/outlier unit price",IF(Y20=1,"Discount greater than order value","")))))))) | AC20: =IF(AB20="","KEEP","DROP") -> KEEP | AD20: =IF(TRIM(F20)="",IFERROR(INDEX(Map_Tables!$I$4:$I$37,MATCH(TRIM(E20),Map_Tables!$G$4:$G$37,0)),""),IFERROR(INDEX(Map_Tables!$B$4:$B$18,MATCH(TRIM(F20),Map_Tables!$A$4:$A$18,0)),"CHECK")) -> Mumbai | AE20: =IF(TRIM(E20)="","",IFERROR(INDEX(Map_Tables!$H$4:$H$37,MATCH(TRIM(E20),Map_Tables!$G$4:$G$37,0)),"CHECK")) -> Pav Bhaji Point | AF20: =IF(TRIM(K20)="","Unknown",IFERROR(INDEX(Map_Tables!$E$4:$E$15,MATCH(TRIM(K20),Map_Tables!$D$4:$D$15,0)),"CHECK")) -> Wallet | AG20: =IF(LEFT(LOWER(TRIM(L20)),6)="cancel","Cancelled","Delivered") -> Delivered | AH20: =IF(ISNUMBER(SEARCH("/",B20)),DATE(VALUE(RIGHT(B20,4)),VALUE(MID(B20,4,2)),VALUE(LEFT(B20,2))),IF(MID(B20,5,1)="-",DATE(VALUE(LEFT(B20,4)),VALUE(MID(B20,6,2)),VALUE(RIGHT(B20,2))),DATE(VALUE(RIGHT(B20,4)),MATCH(MID(B20,4,3),{"Jan","Feb","Mar","Apr","May","Jun","Jul","Aug","Sep","Oct","Nov","Dec"},0),VALUE(LEFT(B20,2))))) -> 45731
A21: ORD10126 | B21: 2025-01-16 | C21: 20:51 | D21: C0365 | E21: Dragon Express | F21: Mumbai | G21: Chinese | H21: 2 | I21: 285 | J21: 0 | K21: UPI | L21: Delivered | M21: 47 | N21: 5 | O21: =A21&"|"&B21&"|"&C21&"|"&D21&"|"&E21&"|"&F21&"|"&G21&"|"&H21&"|"&I21&"|"&J21&"|"&K21&"|"&L21&"|"&M21&"|"&N21 -> ORD10126|2025-01-16|20:51|C0365|Dragon Express|Mumbai|Chinese|2|285|0|UPI|Delivered|47|5 | P21: =IF(COUNTIF($O$2:O21,O21)>1,"DUP","OK") -> OK | Q21: =COUNTBLANK(A21:N21) -> 0 | R21: =IF(A21="",0,COUNTIFS($A$2:$A$3058,A21,$P$2:$P$3058,"OK")) -> 1 | S21: =IF(OR(A21="",P21="DUP",R21<2),"",IF(Q21=_xlfn.MINIFS($Q$2:$Q$3058,$A$2:$A$3058,A21,$P$2:$P$3058,"OK"),"KEEP","DROP")) | T21: =IF(A21="",1,0) -> 0 | U21: =IF(D21="",1,0) -> 0 | V21: =IF(E21="",1,0) -> 0 | W21: =IF(OR(H21<1,H21>10),1,0) -> 0 | X21: =IF(OR(I21<=0,I21>1500),1,0) -> 0 | Y21: =IF(J21>H21*I21,1,0) -> 0 | Z21: =IF(AND(N21<>"",OR(N21<1,N21>5)),1,0) -> 0 | AA21: =IF(AND(M21<>"",OR(M21<5,M21>180)),1,0) -> 0 | AB21: =IF(P21="DUP","Exact duplicate row",IF(T21=1,"Missing Order ID",IF(S21="DROP","Duplicate Order ID (less complete row)",IF(U21=1,"Missing Customer ID",IF(V21=1,"Missing Restaurant name",IF(W21=1,"Invalid/outlier quantity",IF(X21=1,"Invalid/outlier unit price",IF(Y21=1,"Discount greater than order value","")))))))) | AC21: =IF(AB21="","KEEP","DROP") -> KEEP | AD21: =IF(TRIM(F21)="",IFERROR(INDEX(Map_Tables!$I$4:$I$37,MATCH(TRIM(E21),Map_Tables!$G$4:$G$37,0)),""),IFERROR(INDEX(Map_Tables!$B$4:$B$18,MATCH(TRIM(F21),Map_Tables!$A$4:$A$18,0)),"CHECK")) -> Mumbai | AE21: =IF(TRIM(E21)="","",IFERROR(INDEX(Map_Tables!$H$4:$H$37,MATCH(TRIM(E21),Map_Tables!$G$4:$G$37,0)),"CHECK")) -> Dragon Express | AF21: =IF(TRIM(K21)="","Unknown",IFERROR(INDEX(Map_Tables!$E$4:$E$15,MATCH(TRIM(K21),Map_Tables!$D$4:$D$15,0)),"CHECK")) -> UPI | AG21: =IF(LEFT(LOWER(TRIM(L21)),6)="cancel","Cancelled","Delivered") -> Delivered | AH21: =IF(ISNUMBER(SEARCH("/",B21)),DATE(VALUE(RIGHT(B21,4)),VALUE(MID(B21,4,2)),VALUE(LEFT(B21,2))),IF(MID(B21,5,1)="-",DATE(VALUE(LEFT(B21,4)),VALUE(MID(B21,6,2)),VALUE(RIGHT(B21,2))),DATE(VALUE(RIGHT(B21,4)),MATCH(MID(B21,4,3),{"Jan","Feb","Mar","Apr","May","Jun","Jul","Aug","Sep","Oct","Nov","Dec"},0),VALUE(LEFT(B21,2))))) -> 45673
A22: ORD12702 | B22: 28/11/2025 | C22: 20:39 | D22: C0984 | E22: Hyderabad Dum Biryani | F22: Hyderabad | G22: Biryani | H22: 1 | I22: 305 | J22: 122 | K22: UPI | L22: Delivered | M22: 58 | N22: 4 | O22: =A22&"|"&B22&"|"&C22&"|"&D22&"|"&E22&"|"&F22&"|"&G22&"|"&H22&"|"&I22&"|"&J22&"|"&K22&"|"&L22&"|"&M22&"|"&N22 -> ORD12702|28/11/2025|20:39|C0984|Hyderabad Dum Biryani|Hyderabad|Biryani|1|305|122|UPI|Delivered|58|4 | P22: =IF(COUNTIF($O$2:O22,O22)>1,"DUP","OK") -> OK | Q22: =COUNTBLANK(A22:N22) -> 0 | R22: =IF(A22="",0,COUNTIFS($A$2:$A$3058,A22,$P$2:$P$3058,"OK")) -> 1 | S22: =IF(OR(A22="",P22="DUP",R22<2),"",IF(Q22=_xlfn.MINIFS($Q$2:$Q$3058,$A$2:$A$3058,A22,$P$2:$P$3058,"OK"),"KEEP","DROP")) | T22: =IF(A22="",1,0) -> 0 | U22: =IF(D22="",1,0) -> 0 | V22: =IF(E22="",1,0) -> 0 | W22: =IF(OR(H22<1,H22>10),1,0) -> 0 | X22: =IF(OR(I22<=0,I22>1500),1,0) -> 0 | Y22: =IF(J22>H22*I22,1,0) -> 0 | Z22: =IF(AND(N22<>"",OR(N22<1,N22>5)),1,0) -> 0 | AA22: =IF(AND(M22<>"",OR(M22<5,M22>180)),1,0) -> 0 | AB22: =IF(P22="DUP","Exact duplicate row",IF(T22=1,"Missing Order ID",IF(S22="DROP","Duplicate Order ID (less complete row)",IF(U22=1,"Missing Customer ID",IF(V22=1,"Missing Restaurant name",IF(W22=1,"Invalid/outlier quantity",IF(X22=1,"Invalid/outlier unit price",IF(Y22=1,"Discount greater than order value","")))))))) | AC22: =IF(AB22="","KEEP","DROP") -> KEEP | AD22: =IF(TRIM(F22)="",IFERROR(INDEX(Map_Tables!$I$4:$I$37,MATCH(TRIM(E22),Map_Tables!$G$4:$G$37,0)),""),IFERROR(INDEX(Map_Tables!$B$4:$B$18,MATCH(TRIM(F22),Map_Tables!$A$4:$A$18,0)),"CHECK")) -> Hyderabad | AE22: =IF(TRIM(E22)="","",IFERROR(INDEX(Map_Tables!$H$4:$H$37,MATCH(TRIM(E22),Map_Tables!$G$4:$G$37,0)),"CHECK")) -> Hyderabad Dum Biryani | AF22: =IF(TRIM(K22)="","Unknown",IFERROR(INDEX(Map_Tables!$E$4:$E$15,MATCH(TRIM(K22),Map_Tables!$D$4:$D$15,0)),"CHECK")) -> UPI | AG22: =IF(LEFT(LOWER(TRIM(L22)),6)="cancel","Cancelled","Delivered") -> Delivered | AH22: =IF(ISNUMBER(SEARCH("/",B22)),DATE(VALUE(RIGHT(B22,4)),VALUE(MID(B22,4,2)),VALUE(LEFT(B22,2))),IF(MID(B22,5,1)="-",DATE(VALUE(LEFT(B22,4)),VALUE(MID(B22,6,2)),VALUE(RIGHT(B22,2))),DATE(VALUE(RIGHT(B22,4)),MATCH(MID(B22,4,3),{"Jan","Feb","Mar","Apr","May","Jun","Jul","Aug","Sep","Oct","Nov","Dec"},0),VALUE(LEFT(B22,2))))) -> 45989
A23: ORD12440 | B23: 2025-11-03 | C23: 11:51 | D23: C1140 | E23: Hyderabad Dum Biryani | G23: Biryani | H23: 4 | I23: 250 | J23: 150 | K23: UPI | L23: Delivered | M23: 19 | N23: 5 | O23: =A23&"|"&B23&"|"&C23&"|"&D23&"|"&E23&"|"&F23&"|"&G23&"|"&H23&"|"&I23&"|"&J23&"|"&K23&"|"&L23&"|"&M23&"|"&N23 -> ORD12440|2025-11-03|11:51|C1140|Hyderabad Dum Biryani||Biryani|4|250|150|UPI|Delivered|19|5 | P23: =IF(COUNTIF($O$2:O23,O23)>1,"DUP","OK") -> OK | Q23: =COUNTBLANK(A23:N23) -> 1 | R23: =IF(A23="",0,COUNTIFS($A$2:$A$3058,A23,$P$2:$P$3058,"OK")) -> 1 | S23: =IF(OR(A23="",P23="DUP",R23<2),"",IF(Q23=_xlfn.MINIFS($Q$2:$Q$3058,$A$2:$A$3058,A23,$P$2:$P$3058,"OK"),"KEEP","DROP")) | T23: =IF(A23="",1,0) -> 0 | U23: =IF(D23="",1,0) -> 0 | V23: =IF(E23="",1,0) -> 0 | W23: =IF(OR(H23<1,H23>10),1,0) -> 0 | X23: =IF(OR(I23<=0,I23>1500),1,0) -> 0 | Y23: =IF(J23>H23*I23,1,0) -> 0 | Z23: =IF(AND(N23<>"",OR(N23<1,N23>5)),1,0) -> 0 | AA23: =IF(AND(M23<>"",OR(M23<5,M23>180)),1,0) -> 0 | AB23: =IF(P23="DUP","Exact duplicate row",IF(T23=1,"Missing Order ID",IF(S23="DROP","Duplicate Order ID (less complete row)",IF(U23=1,"Missing Customer ID",IF(V23=1,"Missing Restaurant name",IF(W23=1,"Invalid/outlier quantity",IF(X23=1,"Invalid/outlier unit price",IF(Y23=1,"Discount greater than order value","")))))))) | AC23: =IF(AB23="","KEEP","DROP") -> KEEP | AD23: =IF(TRIM(F23)="",IFERROR(INDEX(Map_Tables!$I$4:$I$37,MATCH(TRIM(E23),Map_Tables!$G$4:$G$37,0)),""),IFERROR(INDEX(Map_Tables!$B$4:$B$18,MATCH(TRIM(F23),Map_Tables!$A$4:$A$18,0)),"CHECK")) -> Hyderabad | AE23: =IF(TRIM(E23)="","",IFERROR(INDEX(Map_Tables!$H$4:$H$37,MATCH(TRIM(E23),Map_Tables!$G$4:$G$37,0)),"CHECK")) -> Hyderabad Dum Biryani | AF23: =IF(TRIM(K23)="","Unknown",IFERROR(INDEX(Map_Tables!$E$4:$E$15,MATCH(TRIM(K23),Map_Tables!$D$4:$D$15,0)),"CHECK")) -> UPI | AG23: =IF(LEFT(LOWER(TRIM(L23)),6)="cancel","Cancelled","Delivered") -> Delivered | AH23: =IF(ISNUMBER(SEARCH("/",B23)),DATE(VALUE(RIGHT(B23,4)),VALUE(MID(B23,4,2)),VALUE(LEFT(B23,2))),IF(MID(B23,5,1)="-",DATE(VALUE(LEFT(B23,4)),VALUE(MID(B23,6,2)),VALUE(RIGHT(B23,2))),DATE(VALUE(RIGHT(B23,4)),MATCH(MID(B23,4,3),{"Jan","Feb","Mar","Apr","May","Jun","Jul","Aug","Sep","Oct","Nov","Dec"},0),VALUE(LEFT(B23,2))))) -> 45964
A24: ORD10503 | B24: 07/03/2025 | C24: 14:58 | D24: C1262 | E24: Green Bowl Kitchen | F24: Chennai | G24: Healthy Food | H24: 1 | I24: 315 | J24: 0 | K24: UPI | L24: Delivered | M24: 37 | N24: 5 | O24: =A24&"|"&B24&"|"&C24&"|"&D24&"|"&E24&"|"&F24&"|"&G24&"|"&H24&"|"&I24&"|"&J24&"|"&K24&"|"&L24&"|"&M24&"|"&N24 -> ORD10503|07/03/2025|14:58|C1262|Green Bowl Kitchen|Chennai|Healthy Food|1|315|0|UPI|Delivered|37|5 | P24: =IF(COUNTIF($O$2:O24,O24)>1,"DUP","OK") -> OK | Q24: =COUNTBLANK(A24:N24) -> 0 | R24: =IF(A24="",0,COUNTIFS($A$2:$A$3058,A24,$P$2:$P$3058,"OK")) -> 1 | S24: =IF(OR(A24="",P24="DUP",R24<2),"",IF(Q24=_xlfn.MINIFS($Q$2:$Q$3058,$A$2:$A$3058,A24,$P$2:$P$3058,"OK"),"KEEP","DROP")) | T24: =IF(A24="",1,0) -> 0 | U24: =IF(D24="",1,0) -> 0 | V24: =IF(E24="",1,0) -> 0 | W24: =IF(OR(H24<1,H24>10),1,0) -> 0 | X24: =IF(OR(I24<=0,I24>1500),1,0) -> 0 | Y24: =IF(J24>H24*I24,1,0) -> 0 | Z24: =IF(AND(N24<>"",OR(N24<1,N24>5)),1,0) -> 0 | AA24: =IF(AND(M24<>"",OR(M24<5,M24>180)),1,0) -> 0 | AB24: =IF(P24="DUP","Exact duplicate row",IF(T24=1,"Missing Order ID",IF(S24="DROP","Duplicate Order ID (less complete row)",IF(U24=1,"Missing Customer ID",IF(V24=1,"Missing Restaurant name",IF(W24=1,"Invalid/outlier quantity",IF(X24=1,"Invalid/outlier unit price",IF(Y24=1,"Discount greater than order value","")))))))) | AC24: =IF(AB24="","KEEP","DROP") -> KEEP | AD24: =IF(TRIM(F24)="",IFERROR(INDEX(Map_Tables!$I$4:$I$37,MATCH(TRIM(E24),Map_Tables!$G$4:$G$37,0)),""),IFERROR(INDEX(Map_Tables!$B$4:$B$18,MATCH(TRIM(F24),Map_Tables!$A$4:$A$18,0)),"CHECK")) -> Chennai | AE24: =IF(TRIM(E24)="","",IFERROR(INDEX(Map_Tables!$H$4:$H$37,MATCH(TRIM(E24),Map_Tables!$G$4:$G$37,0)),"CHECK")) -> Green Bowl Kitchen | AF24: =IF(TRIM(K24)="","Unknown",IFERROR(INDEX(Map_Tables!$E$4:$E$15,MATCH(TRIM(K24),Map_Tables!$D$4:$D$15,0)),"CHECK")) -> UPI | AG24: =IF(LEFT(LOWER(TRIM(L24)),6)="cancel","Cancelled","Delivered") -> Delivered | AH24: =IF(ISNUMBER(SEARCH("/",B24)),DATE(VALUE(RIGHT(B24,4)),VALUE(MID(B24,4,2)),VALUE(LEFT(B24,2))),IF(MID(B24,5,1)="-",DATE(VALUE(LEFT(B24,4)),VALUE(MID(B24,6,2)),VALUE(RIGHT(B24,2))),DATE(VALUE(RIGHT(B24,4)),MATCH(MID(B24,4,3),{"Jan","Feb","Mar","Apr","May","Jun","Jul","Aug","Sep","Oct","Nov","Dec"},0),VALUE(LEFT(B24,2))))) -> 45723
